Workbook

Sheet sheet1
A1: 缝纫周生产计划（表头红色字体只有参考不做生产标准） | AY1: 友情提醒：这四列的量只是为了区分生产线左右边不是要安排生产的量 | BK1: 每天更新一次 | BO1: C21开头的布会缩一定要注意 | BQ1: 每天更新一次 | BU1: C21开头的布会缩一定要注意
A3: 客户 | B3: 课别 | C3: 区域 | D3: 日期 Date | J3: 生产线情况 | K3: 生产线类别 | L3: 20220804更新检验人员 | M3: 11小时产量/班（技术的BJ产能） | N3: 20230804更新缝纫人员 | O3: 20220804更新检验人员 | P3: 合计 | Q3: 46239 | S3: 46240 | U3: 46241 | W3: 46242 | Y3: 46243 | AA3: 46244 | AC3: 46245 | AE3: 46246 | AG3: 46247 | AI3: 46248 | AK3: 46249 | AM3: 46250 | AO3: 46251 | AQ3: 46252 | AS3: 46253 | AU3: 46254 | AW3: 46255 | AY3: 46256 | BA3: 46257 | BC3: 46258 | BE3: 实际产能 | BG3: 满箱数量 | BI3: 布 | BJ3: 单耗 | BK3: 切割 | BL3: A级库存量 | BM3: 待成检+待缴库 | BN3: 待上胶 | BQ3: 切割 | BR3: A级库存量 | BS3: 待成检+待缴库 | BT3: 待上胶 | BW3: 给业务最大产量
D4: 年Year:2026 周Week:33 | Q4: 星期三 | S4: 星期四 | U4: 星期五 | W4: 星期六 | Y4: 星期日 | AA4: 星期一 | AC4: 星期二 | AE4: 星期三 | AG4: 星期四 | AI4: 星期五 | AK4: 星期六 | AM4: 星期日 | AO4: 星期一 | AQ4: 星期二 | AS4: 星期三 | AU4: 星期四 | AW4: 星期五 | AY4: 星期六 | BA4: 星期日 | BC4: 星期一 | BH4: 业务出货量 | BO4: 可以生产多少袋子 | BU4: 可以生产多少袋子
D5: 生产线 | E5: 零件号 | F5: 产品名称 | G5: SAP物料号 | H5: 零件名称 | I5: 基布 | Q5: 早 | R5: 夜 | S5: 早 | T5: 夜 | U5: 早 | V5: 夜 | W5: 早 | X5: 夜 | Y5: 早 | Z5: 夜 | AA5: 早 | AB5: 夜 | AC5: 早 | AD5: 夜 | AE5: 早 | AF5: 夜 | AG5: 早 | AH5: 夜 | AI5: 早 | AJ5: 夜 | AK5: 早 | AL5: 夜 | AM5: 早 | AN5: 夜 | AO5: 早 | AP5: 夜 | AQ5: 早 | AR5: 夜 | AS5: 早 | AT5: 夜 | AU5: 早 | AV5: 夜 | AW5: 早 | AX5: 夜 | AY5: 早 | AZ5: 夜 | BA5: 早 | BB5: 夜 | BC5: 早 | BD5: 夜 | BE5: 早 | BF5: 夜
A6: 临港均胜 | B6: 二课 | C6: B1 | D6: S0109 | E6: 155S17BL | F6: =VLOOKUP(E6,[1]库存!$B$1:$C$65536,2,FALSE) -> B311 SAB LH （埃） | G6: 000000008000002759 | H6: B311 SAB LH （埃） | I6: P31131 H41132 P40431 H22411 | J6: 20260104业务通知不备货 | L6: 2 | M6: 1700 | N6: 10 | O6: 2 | P6: =SUM(AG6:AJ6) -> 0 | BI6: 0 | BJ6: 0 | BK6: 0 | BL6: 0 | BM6: 0 | BN6: 0 | BQ6: 0 | BR6: 0 | BS6: 0 | BT6: 0
A7: 0 | B7: 0 | C7: 0 | F7: =VLOOKUP(E7,[1]库存!$B$1:$C$65536,2,FALSE) -> #N/A | G7: #N/A | L7: 0 | M7: 0 | N7: 0 | O7: 0 | P7: =SUM(AG7:AJ7) -> 0 | BI7: 0 | BJ7: 0 | BK7: 0 | BL7: 0 | BM7: 0 | BN7: 0 | BQ7: 0 | BR7: 0 | BS7: 0 | BT7: 0
A8: 临港均胜 | B8: 二课 | C8: B1 | D8: S0109 | E8: 155S17BR | F8: =VLOOKUP(E8,[1]库存!$B$1:$C$65536,2,FALSE) -> B311 SAB RH （埃） | G8: 000000008000002760 | H8: B311 SAB RH （埃） | I8: P31131 H41132 P40431 H22411 | L8: 2 | M8: 1700 | N8: 10 | O8: 2 | P8: =SUM(AG8:AJ8) -> 0 | BI8: 0 | BJ8: 0 | BK8: 0 | BL8: 0 | BM8: 0 | BN8: 0 | BQ8: 0 | BR8: 0 | BS8: 0 | BT8: 0
A9: 0 | B9: 0 | C9: 0 | F9: =VLOOKUP(E9,[1]库存!$B$1:$C$65536,2,FALSE) -> #N/A | G9: #N/A | L9: 0 | M9: 0 | N9: 0 | O9: 0 | P9: =SUM(AG9:AJ9) -> 0 | BI9: 0 | BJ9: 0 | BK9: 0 | BL9: 0 | BM9: 0 | BN9: 0 | BQ9: 0 | BR9: 0 | BS9: 0 | BT9: 0
A10: 0 | B10: 二课 | C10: B1 | D10: S0109 | E10: 147S29L | F10: =VLOOKUP(E10,[1]库存!$B$1:$C$65536,2,FALSE) -> SGM 258 EXT SAB LH | G10: 000000008000001184 | H10: SGM 258 EXT SAB LH | I10: P31131 H22412 P40431 H41132 | J10: 20241024业务EOP调查10月31号开始收尾11月8号收尾完成 | L10: 1.5 | M10: 1550 | N10: 10 | O10: 1.5 | P10: =SUM(AG10:AJ10) -> 0 | BI10: 0 | BJ10: 0 | BK10: 0 | BL10: 0 | BM10: 0 | BN10: 0 | BQ10: 0 | BR10: 0 | BS10: 0 | BT10: 0
A11: 0 | B11: 0 | C11: 0 | F11: =VLOOKUP(E11,[1]库存!$B$1:$C$65536,2,FALSE) -> #N/A | G11: #N/A | L11: 0 | M11: 0 | N11: 0 | O11: 0 | P11: =SUM(AG11:AJ11) -> 0 | BI11: 0 | BJ11: 0 | BK11: 0 | BL11: 0 | BM11: 0 | BN11: 0 | BQ11: 0 | BR11: 0 | BS11: 0 | BT11: 0
A12: 0 | B12: 二课 | C12: B1 | D12: S0109 | E12: 147S29R | F12: =VLOOKUP(E12,[1]库存!$B$1:$C$65536,2,FALSE) -> SGM 258 EXT SAB RH | G12: 000000008000001185 | H12: SGM 258 EXT SAB RH | I12: P31131 H22412 P40431 H41132 | L12: 1.5 | M12: 1550 | N12: 10 | O12: 1.5 | P12: =SUM(AG12:AJ12) -> 0 | BI12: 0 | BJ12: 0 | BK12: 0 | BL12: 0 | BM12: 0 | BN12: 0 | BQ12: 0 | BR12: 0 | BS12: 0 | BT12: 0
A13: 0 | B13: 0 | C13: 0 | F13: =VLOOKUP(E13,[1]库存!$B$1:$C$65536,2,FALSE) -> #N/A | G13: #N/A | L13: 0 | M13: 0 | N13: 0 | O13: 0 | P13: =SUM(AG13:AJ13) -> 0 | BI13: 0 | BJ13: 0 | BK13: 0 | BL13: 0 | BM13: 0 | BN13: 0 | BQ13: 0 | BR13: 0 | BS13: 0 | BT13: 0
A14: 0 | B14: 二课 | C14: B1 | D14: S0109 | E14: 14CS56L | F14: =VLOOKUP(E14,[1]库存!$B$1:$C$65536,2,FALSE) -> SGM 358 SAB LH | G14: 000000008000001190 | H14: SGM 358 SAB LH | I14: P31131 H22411 P40431 | J14: 量少按业务预估 | L14: 2 | M14: 1400 | N14: 13 | O14: 2 | P14: =SUM(AG14:AJ14) -> 0
A15: 0 | B15: 0 | C15: 0 | F15: =VLOOKUP(E15,[1]库存!$B$1:$C$65536,2,FALSE) -> #N/A | G15: #N/A | L15: 0 | M15: 0 | N15: 0 | O15: 0 | P15: =SUM(AG15:AJ15) -> 0
A16: 0 | B16: 二课 | C16: B1 | D16: S0109 | E16: 14CS56R | F16: =VLOOKUP(E16,[1]库存!$B$1:$C$65536,2,FALSE) -> SGM 358 SAB RH | G16: 000000008000001191 | H16: SGM 358 SAB RH | I16: P31131 H22411 P40431 | J16: 量少按业务预估 | L16: 2 | M16: 1400 | N16: 13 | O16: 2 | P16: =SUM(AG16:AJ16) -> 0
A17: 0 | B17: 0 | C17: 0 | F17: =VLOOKUP(E17,[1]库存!$B$1:$C$65536,2,FALSE) -> #N/A | G17: #N/A | L17: 0 | M17: 0 | N17: 0 | O17: 0 | P17: =SUM(AG17:AJ17) -> 0
A18: 临港均胜 | B18: 二课 | C18: B1 | D18: S0109 | E18: 157S22L | F18: =VLOOKUP(E18,[1]库存!$B$1:$C$65536,2,FALSE) -> CHANGAN C202 VAVE SABL | G18: 000000008000001200 | H18: CHANGAN C202 VAVE SABL | I18: P31131 H22411 H41132 | J18: 量少按业务预估 | L18: 2 | M18: 1320 | N18: 12 | O18: 2 | P18: =SUM(AG18:AJ18) -> 0
A19: 0 | B19: 0 | C19: 0 | F19: =VLOOKUP(E19,[1]库存!$B$1:$C$65536,2,FALSE) -> #N/A | G19: #N/A | L19: 0 | M19: 0 | N19: 0 | O19: 0 | P19: =SUM(AG19:AJ19) -> 0
A20: 0 | B20: 二课 | C20: B1 | D20: S0109 | E20: 157S22R | F20: =VLOOKUP(E20,[1]库存!$B$1:$C$65536,2,FALSE) -> CHANGAN C202 VAVE SABR | G20: 000000008000001201 | H20: CHANGAN C202 VAVE SABR | I20: P31131 H22411 H41132 | J20: 量少按业务预估 | L20: 2 | M20: 1320 | N20: 12 | O20: 2 | P20: =SUM(AG20:AJ20) -> 0
A21: 0 | B21: 0 | C21: 0 | F21: =VLOOKUP(E21,[1]库存!$B$1:$C$65536,2,FALSE) -> #N/A | G21: #N/A | L21: 0 | M21: 0 | N21: 0 | O21: 0 | P21: =SUM(AG21:AJ21) -> 0
A22: 0 | B22: 二课 | C22: B1 | D22: S0109 | E22: 124S07L | F22: =VLOOKUP(E22,[1]库存!$B$1:$C$65536,2,FALSE) -> CHANA S101 SAB-LH | G22: 000000008000001047 | H22: CHANA S101 SAB-LH | I22: H31532 H40232 | J22: 售后件 | L22: 2 | M22: 1650 | N22: 6 | O22: 2 | P22: =SUM(AG22:AJ22) -> 0 | BI22: 0 | BJ22: 0 | BK22: 0 | BL22: 0 | BM22: 0 | BN22: 0 | BQ22: 0 | BR22: 0 | BS22: 0 | BT22: 0
A23: 0 | B23: 0 | C23: 0 | F23: =VLOOKUP(E23,[1]库存!$B$1:$C$65536,2,FALSE) -> #N/A | G23: #N/A | L23: 0 | M23: 0 | N23: 0 | O23: 0 | P23: =SUM(AG23:AJ23) -> 0 | BI23: 0 | BJ23: 0 | BK23: 0 | BL23: 0 | BM23: 0 | BN23: 0 | BQ23: 0 | BR23: 0 | BS23: 0 | BT23: 0
A24: 0 | B24: 二课 | C24: B1 | D24: S0109 | E24: 124S07R | F24: =VLOOKUP(E24,[1]库存!$B$1:$C$65536,2,FALSE) -> CHANA S101 SAB-RH | G24: 000000008000001048 | H24: CHANA S101 SAB-RH | I24: H31532 H40232 | J24: 售后件 | L24: 2 | M24: 1650 | N24: 6 | O24: 2 | P24: =SUM(AG24:AJ24) -> 0 | BI24: 0 | BJ24: 0 | BK24: 0 | BL24: 0 | BM24: 0 | BN24: 0 | BQ24: 0 | BR24: 0 | BS24: 0 | BT24: 0
A25: 0 | B25: 0 | C25: 0 | F25: =VLOOKUP(E25,[1]库存!$B$1:$C$65536,2,FALSE) -> #N/A | G25: #N/A | L25: 0 | M25: 0 | N25: 0 | O25: 0 | P25: =SUM(AG25:AJ25) -> 0 | BI25: 0 | BJ25: 0 | BK25: 0 | BL25: 0 | BM25: 0 | BN25: 0 | BQ25: 0 | BR25: 0 | BS25: 0 | BT25: 0
A26: 0 | B26: 二课 | C26: B1 | D26: S0109 | E26: 14AS49L | F26: =VLOOKUP(E26,[1]库存!$B$1:$C$65536,2,FALSE) -> BAIC C51E SAB LH | G26: 000000008000001188 | H26: BAIC C51E SAB LH | I26: P31131 H41132 H21011 | J26: 售后件 | L26: 2 | M26: 1400 | N26: 8 | O26: 2 | P26: =SUM(AG26:AJ26) -> 0 | BI26: 0 | BJ26: 0 | BK26: 0 | BL26: 0 | BM26: 0 | BN26: 0 | BQ26: 0 | BR26: 0 | BS26: 0 | BT26: 0
A27: 0 | B27: 0 | C27: 0 | F27: =VLOOKUP(E27,[1]库存!$B$1:$C$65536,2,FALSE) -> #N/A | G27: #N/A | L27: 0 | M27: 0 | N27: 0 | O27: 0 | P27: =SUM(AG27:AJ27) -> 0 | BI27: 0 | BJ27: 0 | BK27: 0 | BL27: 0 | BM27: 0 | BN27: 0 | BQ27: 0 | BR27: 0 | BS27: 0 | BT27: 0
A28: 0 | B28: 二课 | C28: B1 | D28: S0109 | E28: 14AS49R | F28: =VLOOKUP(E28,[1]库存!$B$1:$C$65536,2,FALSE) -> BAIC C51E SAB RH | G28: 000000008000001189 | H28: BAIC C51E SAB RH | I28: P31131 H41132 H21011 | J28: 售后件 | L28: 2 | M28: 1400 | N28: 8 | O28: 2 | P28: =SUM(AG28:AJ28) -> 0 | BI28: 0 | BJ28: 0 | BK28: 0 | BL28: 0 | BM28: 0 | BN28: 0 | BQ28: 0 | BR28: 0 | BS28: 0 | BT28: 0
A29: 0 | B29: 0 | C29: 0 | F29: =VLOOKUP(E29,[1]库存!$B$1:$C$65536,2,FALSE) -> #N/A | G29: #N/A | L29: 0 | M29: 0 | N29: 0 | O29: 0 | P29: =SUM(AG29:AJ29) -> 0 | BI29: 0 | BJ29: 0 | BK29: 0 | BL29: 0 | BM29: 0 | BN29: 0 | BQ29: 0 | BR29: 0 | BS29: 0 | BT29: 0
A30: 0 | B30: 0 | C30: 0 | F30: =VLOOKUP(E30,[1]库存!$B$1:$C$65536,2,FALSE) -> #N/A | G30: #N/A | L30: 0 | M30: 0 | N30: 0 | O30: 0 | P30: =SUM(AG30:AJ30) -> 0 | BI30: 0 | BJ30: 0 | BK30: 0 | BL30: 0 | BM30: 0 | BN30: 0 | BQ30: 0 | BR30: 0 | BS30: 0 | BT30: 0
A31: 0 | B31: 二课 | C31: B1 | D31: S0108 | E31: 141S01 | F31: =VLOOKUP(E31,[1]库存!$B$1:$C$65536,2,FALSE) -> SVW NMS RSAB | G31: 000000008000001175 | H31: SVW NMS RSAB | I31: P40431 H22411 | L31: 2 | M31: 1200 | N31: 13 | O31: 2 | P31: =SUM(AG31:AJ31) -> 0 | BI31: 0 | BJ31: 0 | BK31: 0 | BL31: 0 | BM31: 0 | BN31: 0 | BQ31: 0 | BR31: 0 | BS31: 0 | BT31: 0
A32: 0 | B32: 0 | C32: 0 | F32: =VLOOKUP(E32,[1]库存!$B$1:$C$65536,2,FALSE) -> #N/A | G32: #N/A | L32: 0 | M32: 0 | N32: 0 | O32: 0 | P32: =SUM(AG32:AJ32) -> 0 | BI32: 0 | BJ32: 0 | BK32: 0 | BL32: 0 | BM32: 0 | BN32: 0 | BQ32: 0 | BR32: 0 | BS32: 0 | BT32: 0
A33: 延锋智能 | B33: 二课 | C33: B1 | D33: S0108 | E33: 178S41BL | F33: =VLOOKUP(E33,[1]库存!$B$1:$C$65536,2,FALSE) -> SMCV SV51 SAB LH B状态 | G33: 000000008000005091 | H33: SMCV SV51 SAB LH B状态 | I33: H22412 P31141 P40431 H61332 | L33: 2 | M33: 1200 | N33: 13 | O33: 2 | P33: =SUM(AG33:AJ33) -> 0 | BI33: 0 | BJ33: 0 | BK33: 0 | BL33: 0 | BM33: 0 | BN33: 0 | BQ33: 0 | BR33: 0 | BS33: 0 | BT33: 0
A34: 0 | B34: 0 | C34: 0 | F34: =VLOOKUP(E34,[1]库存!$B$1:$C$65536,2,FALSE) -> #N/A | G34: #N/A | L34: 0 | M34: 0 | N34: 0 | O34: 0 | P34: =SUM(AG34:AJ34) -> 0 | BI34: 0 | BJ34: 0 | BK34: 0 | BL34: 0 | BM34: 0 | BN34: 0 | BQ34: 0 | BR34: 0 | BS34: 0 | BT34: 0
A35: 延锋智能 | B35: 二课 | C35: B1 | D35: S0108 | E35: 178S41BR | F35: =VLOOKUP(E35,[1]库存!$B$1:$C$65536,2,FALSE) -> SMCV SV51 SAB RH B状态 | G35: 000000008000005092 | H35: SMCV SV51 SAB RH B状态 | I35: H22412 P31141 P40431 H61332 | L35: 2 | M35: 1200 | N35: 13 | O35: 2 | P35: =SUM(AG35:AJ35) -> 0 | BI35: 0 | BJ35: 0 | BK35: 0 | BL35: 0 | BM35: 0 | BN35: 0 | BQ35: 0 | BR35: 0 | BS35: 0 | BT35: 0
A36: 0 | B36: 0 | C36: 0 | F36: =VLOOKUP(E36,[1]库存!$B$1:$C$65536,2,FALSE) -> #N/A | G36: #N/A | L36: 0 | M36: 0 | N36: 0 | O36: 0 | P36: =SUM(AG36:AJ36) -> 0 | BI36: 0 | BJ36: 0 | BK36: 0 | BL36: 0 | BM36: 0 | BN36: 0 | BQ36: 0 | BR36: 0 | BS36: 0 | BT36: 0
A37: 延锋智能 | B37: 二课 | C37: B1 | D37: S0108 | E37: 20BS004AL | F37: =VLOOKUP(E37,[1]库存!$B$1:$C$65536,2,FALSE) -> SAIC EP22 MCE EU SAB LH A状态 | G37: 000000008000005099 | H37: SAIC EP22 MCE EU SAB LH A状态 | I37: H21012 H61732 H61332 | L37: 2 | M37: 1200 | N37: 13 | O37: 2 | P37: =SUM(AG37:AJ37) -> 0 | U37: 1280 | BI37: 0 | BJ37: 0 | BK37: 0 | BL37: 0 | BM37: 0 | BN37: 0 | BQ37: 0 | BR37: 0 | BS37: 0 | BT37: 0
A38: 0 | B38: 0 | C38: 0 | F38: =VLOOKUP(E38,[1]库存!$B$1:$C$65536,2,FALSE) -> #N/A | G38: #N/A | L38: 0 | M38: 0 | N38: 0 | O38: 0 | P38: =SUM(AG38:AJ38) -> 0 | U38: 1297 | BI38: 0 | BJ38: 0 | BK38: 0 | BL38: 0 | BM38: 0 | BN38: 0 | BQ38: 0 | BR38: 0 | BS38: 0 | BT38: 0
A39: 延锋智能 | B39: 二课 | C39: B1 | D39: S0108 | E39: 20BS004AR | F39: =VLOOKUP(E39,[1]库存!$B$1:$C$65536,2,FALSE) -> SAIC EP22 MCE EU SAB RH A状态 | G39: 000000008000005100 | H39: SAIC EP22 MCE EU SAB RH A状态 | I39: H21012 H61732 H61332 | L39: 2 | M39: 1200 | N39: 13 | O39: 2 | P39: =SUM(AG39:AJ39) -> 0 | BI39: 0 | BJ39: 0 | BK39: 0 | BL39: 0 | BM39: 0 | BN39: 0 | BQ39: 0 | BR39: 0 | BS39: 0 | BT39: 0
A40: 0 | B40: 0 | C40: 0 | F40: =VLOOKUP(E40,[1]库存!$B$1:$C$65536,2,FALSE) -> #N/A | G40: #N/A | L40: 0 | M40: 0 | N40: 0 | O40: 0 | P40: =SUM(AG40:AJ40) -> 0 | BI40: 0 | BJ40: 0 | BK40: 0 | BL40: 0 | BM40: 0 | BN40: 0 | BQ40: 0 | BR40: 0 | BS40: 0 | BT40: 0
A41: 延锋智能 | B41: 二课 | C41: B1 | D41: S0108 | E41: 206S38L | F41: =VLOOKUP(E41,[1]库存!$B$1:$C$65536,2,FALSE) -> SAIC EP21 MCE EU SAB LH | G41: 000000008000002384 | H41: 206S38L SAIC EP21 MCE EU SAB LH | I41: H40242 H41132 H21012 | J41: 量少按业务预估 | L41: 2 | M41: 1200 | N41: 13 | O41: 2 | P41: =SUM(AG41:AJ41) -> 0 | BI41: 0 | BJ41: 0 | BK41: 0 | BL41: 0 | BM41: 0 | BN41: 0 | BQ41: 0 | BR41: 0 | BS41: 0 | BT41: 0
...
